Workbook
Name zoned: '2013 Table 11 CWTs exp'!#REF!
Name zoned: '2014 Table 11 CWTs exp'!#REF!
Name zoned: '2015 Table 11 CWTs exp'!#REF!
Name zoned: '2016 Table 11 CWTs exp'!#REF!
Name zoned: '2017 Table 10 CWTs exp'!#REF!
Name zoned: '2018 Table 10 CWTs exp'!#REF!
Name zoned: '2019 Table 10 CWTs exp'!#REF!
Name zoned: '2020 Table 10 CWTs exp '!#REF!
Name zoned: '2021 Table 10 CWTs exp'!#REF!

Sheet Table 6.Inland 2010 Tag Summary
A1: Table 6. Raw and expanded Central Valley coded-wire-tag (CWT) recoveries by stock and age, brood years 2005-2009
B4: Fall | C4: 2009 | D4: 2008 | E4: 2007 | F4: 2006 | G4: 2005 | H4: 2004 | J4: Total CV CWTs | K4: Total CV %
B5: Age | C5: 1 | D5: 2 | E5: 3 | F5: 4 | G5: 5 | H5: 6
A7: Raw CWT Recoveries | C7: 36 | D7: 7087 | E7: 8022 | F7: 272 | G7: 2 | J7: =SUM(C7:G7) -> 15419 | K7: 62%
C8: (< 1%) | D8: (46%) | E8: (52%) | F8: (2%) | G8: (< 1%)
A10: Expanded CWTtotal | C10: 137.09 | D10: 29450.82 | E10: 63868.43 | F10: 2197 | G10: 2.05 | J10: =SUM(C10:G10) -> 95655.39 | K10: 84%
C11: (< 1%) | D11: (31%) | E11: (67%) | F11: (2%) | G11: (< 1%)
B13: Spring | C13: 2009 | D13: 2008 | E13: 2007 | F13: 2006 | G13: 2005 | H13: 2004 | J13: Total CV CWTs | K13: Total CV %
B14: Age | C14: 1 | D14: 2 | E14: 3 | F14: 4 | G14: 5 | H14: 6
A16: Raw CWT Recoveries | D16: 306 | E16: 3340 | F16: 91 | G16: 1 | J16: =SUM(C16:G16) -> 3738 | K16: 15%
D17: (8%) | E17: (89%) | F17: (2%) | G17: (< 1%)
A19: Expanded CWTtotal | D19: 607.58 | E19: 10582.36 | F19: 307.67 | G19: 1.03 | J19: =SUM(C19:G19) -> 11498.64 | K19: 10%
D20: (5%) | E20: (92%) | F20: (3%) | G20: (< 1%)
B22: Late Fall | C22: 2010 | D22: 2009 | E22: 2008 | F22: 2007 | G22: 2006 | H22: 2005 | J22: Total CV CWTs | K22: Total CV %
B23: Age | C23: 1 | D23: 2 | E23: 3 | F23: 4 | G23: 5 | H23: 6
A25: Raw CWT Recoveries | D25: 153 | E25: 781 | F25: 3824 | G25: 918 | H25: 5 | J25: =SUM(D25:H25) -> 5681 | K25: 23%
D26: (3%) | E26: (14%) | F26: (67%) | G26: (16%) | H26: (< 1%)
A28: Expanded CWTtotal | D28: 333.97 | E28: 1358.34 | F28: 4092.5 | G28: 1122.24 | H28: 5.12 | J28: =SUM(D28:H28) -> 6912.17 | K28: 6%
D29: (5%) | E29: (20%) | F29: (59%) | G29: (16%) | H29: (< 1%)
B31: All Runs | J31: Total CV CWTs | K31: Total CV %
B32: Age | C32: 1 | D32: 2 | E32: 3 | F32: 4 | G32: 5 | H32: 6
A34: Raw CWT Recoveries | C34: =C7+C16 -> 36 | D34: =D7+D16+D25 -> 7546 | E34: =E7+E16+E25 -> 12143 | F34: =F7+F16+F25 -> 4187 | G34: =G7+G16+G25 -> 921 | H34: =H25 -> 5 | J34: =SUM(C34:H34) -> 24838 | K34: 100%
C35: (< 1%) | D35: (30%) | E35: (49%) | F35: (17%) | G35: (4%) | H35: (< 1%)
A37: Expanded CWTtotal | C37: =C10+C19 -> 137.09 | D37: =D10+D19+D28 -> 30392.37 | E37: =E10+E19+E28 -> 75809.13 | F37: =F10+F19+F28 -> 6597.17 | G37: =G10+G19+G28 -> 1125.32 | H37: =H28 -> 5.12 | J37: =SUM(C37:H37) -> 114066.2 | K37: 100%
C38: (< 1%) | D38: (27%) | E38: (66%) | F38: (6%) | G38: (1%) | H38: (< 1%)
D39: `

Sheet cv catch sample 2010
A1: Appendix 1. 2010 Central Valley Chinook hatchery and natural escapement sampling and CWT recovery summary | O1: 82311
A2: CV hatchery - fall
A3: year | B3: fishery | C3: Sample site | D3: sample method | E3: sampled run | F3: total estimate | G3: sampled | H3: sample rate | I3: ad-clips obsvd | J3: ad-clip rate | K3: valid CWTs | L3: hatchery component | M3: natural component | N3: hatchery | O3: natural
A4: 2010 | B4: 50 | C4: Coleman Hatchery fall | D4: actual count | E4: fall | F4: ='[2]raw data'!E11 -> 17238 | G4: ='[2]raw data'!F11 -> 17238 | H4: =G4/F4 -> 1 | I4: ='[2]raw data'!H11 -> 4140 | J4: =I4/G4 -> 0.24016707 | K4: ='[2]raw data'!I11 -> 4040 | L4: =F4-M4 -> 15320.66 | M4: ='[2]raw data'!K11 -> 1917.34 | N4: =L4/F4 -> 0.88877248 | O4: =M4/F4 -> 0.11122752
A5: 2010 | B5: 50 | C5: Feather R Hatchery fall | D5: actual count | E5: fall | F5: ='[2]raw data'!E12 -> 19972 | G5: ='[2]raw data'!F12 -> 19972 | H5: =G5/F5 -> 1 | I5: ='[2]raw data'!H12 -> 6373 | J5: =I5/G5 -> 0.31909674 | K5: ='[2]raw data'!I12 -> 6049 | L5: =F5-M5 -> 18902.19 | M5: ='[2]raw data'!K12 -> 1069.81 | N5: =L5/F5 -> 0.94643451 | O5: =M5/F5 -> 0.053565492
A6: 2010 | B6: 50 | C6: Nimbus Hatchery fall | D6: actual count | E6: fall | F6: ='[2]raw data'!E10 -> 9095 | G6: ='[2]raw data'!F10 -> 9095 | H6: =G6/F6 -> 1 | I6: ='[2]raw data'!H10 -> 2060 | J6: =I6/G6 -> 0.22649808 | K6: ='[2]raw data'!I10 -> 2025 | L6: =F6-M6 -> 7179.34 | M6: ='[2]raw data'!K10 -> 1915.66 | N6: =L6/F6 -> 0.78937218 | O6: =M6/F6 -> 0.21062782
A7: 2010 | B7: 50 | C7: Mokelumne Hatchery fall | D7: actual count | E7: fall | F7: ='[2]raw data'!E14 -> 5276 | G7: ='[2]raw data'!F14 -> 5276 | H7: =G7/F7 -> 1 | I7: ='[2]raw data'!H14 -> 2747 | J7: =I7/G7 -> 0.52065959 | K7: ='[2]raw data'!I14 -> 2707 | L7: =F7-M7 -> 4735.92 | M7: ='[2]raw data'!K14 -> 540.08 | N7: =L7/F7 -> 0.89763457 | O7: =M7/F7 -> 0.10236543
A8: 2010 | B8: 50 | C8: Merced Hatchery fall | D8: actual count | E8: fall | F8: ='[2]raw data'!E13 -> 146 | G8: ='[2]raw data'!F13 -> 146 | H8: =G8/F8 -> 1 | I8: ='[2]raw data'!H13 -> 83 | J8: =I8/G8 -> 0.56849315 | K8: ='[2]raw data'!I13 -> 81 | L8: =F8-M8 -> 114.9 | M8: ='[2]raw data'!K13 -> 31.1 | N8: =L8/F8 -> 0.7869863 | O8: =M8/F8 -> 0.2130137
E9: CV hatchery fall total | F9: =SUM(F4:F8) -> 51727 | G9: =SUM(G4:G8) -> 51727 | H9: =G9/F9 -> 1 | I9: =SUM(I4:I8) -> 15403 | J9: =I9/G9 -> 0.29777486 | K9: =SUM(K4:K8) -> 14902 | L9: =SUM(L4:L8) -> 46253.01 | M9: =SUM(M4:M8) -> 5473.99 | N9: =L9/F9 -> 0.89417538 | O9: =M9/F9 -> 0.10582462
A10: SR natural - fall
A11: year | B11: fishery | C11: Sample site | D11: sample method | E11: sampled run | F11: total estimate | G11: sampled | H11: sample rate | I11: ad-clips obsvd | J11: ad-clip rate | K11: valid CWTs | L11: hatchery component | M11: natural component | N11: hatchery | O11: natural
A12: 2010 | B12: 54 | C12: Upper Sac | D12: mark-recapture | E12: fall | F12: ='[2]raw data'!E22 -> 16372 | G12: ='[2]raw data'!F22 -> 1415 | H12: =G12/F12 -> 0.086428048 | I12: ='[2]raw data'!H22 -> 130 | J12: =I12/G12 -> 0.091872792 | K12: ='[2]raw data'!I22 -> 117 | L12: =F12-M12 -> 3226.39 | M12: ='[2]raw data'!K22 -> 13145.61 | N12: =L12/F12 -> 0.19706755 | O12: =M12/F12 -> 0.80293245
A13: 2010 | B13: 54 | C13: Clear Crk | D13: mark-recapture | E13: fall | F13: ='[2]raw data'!E17 -> 7192 | G13: ='[2]raw data'!F17 -> 1496 | H13: =G13/F13 -> 0.2080089 | I13: ='[2]raw data'!H17 -> 19 | J13: =I13/G13 -> 0.012700535 | K13: ='[2]raw data'!I17 -> 19 | L13: =F13-M13 -> 301.23 | M13: ='[2]raw data'!K17 -> 6890.77 | N13: =L13/F13 -> 0.041884038 | O13: =M13/F13 -> 0.95811596
A14: 2010 | B14: 54 | C14: Butte Crk | D14: mark-recapture | E14: fall | F14: ='[2]raw data'!E16 -> 370 | G14: ='[2]raw data'!F16 -> 83 | H14: =G14/F14 -> 0.22432432 | I14: ='[2]raw data'!H16 -> 3 | J14: =I14/G14 -> 0.036144578 | K14: ='[2]raw data'!I16 -> 3 | L14: =F14-M14 -> 40.18 | M14: ='[2]raw data'!K16 -> 329.82 | N14: =L14/F14 -> 0.10859459 | O14: =M14/F14 -> 0.89140541
A15: 2010 | B15: 54 | C15: Mill Crk | D15: redd count | E15: fall | F15: ='[2]raw data'!E21 -> 144 | G15: ='[2]raw data'!F21 -> 144 | H15: =G15/F15 -> 1 | I15: ='[2]raw data'!H21 -> 1 | J15: =I15/G15 -> 0.0069444444 | K15: ='[2]raw data'!I21 -> 1 | L15: =F15-M15 -> 4.05 | M15: ='[2]raw data'!K21 -> 139.95 | N15: =L15/F15 -> 0.028125 | O15: =M15/F15 -> 0.971875
A16: 2010 | B16: 54 | C16: Deer Crk | D16: redd count | E16: fall | F16: ='[2]raw data'!E18 -> 166 | G16: ='[2]raw data'!F18 -> 166 | H16: =G16/F16 -> 1 | I16: ='[2]raw data'!H18 -> 2 | J16: =I16/G16 -> 0.012048193 | K16: ='[2]raw data'!I18 -> 2 | L16: =F16-M16 -> 5.11 | M16: ='[2]raw data'!K18 -> 160.89 | N16: =L16/F16 -> 0.030783133 | O16: =M16/F16 -> 0.96921687
A17: 2010 | B17: 54 | C17: Feather River | D17: mark-recapture | E17: fall | F17: ='[2]raw data'!E19 -> 44914 | G17: ='[2]raw data'!F19 -> 5077 | H17: =G17/F17 -> 0.11303825 | I17: 1388 | J17: =I17/G17 -> 0.2733898 | K17: ='[2]raw data'!I19 -> 1276 | L17: =F17-M17 -> 34980.6 | M17: ='[2]raw data'!K19 -> 9933.4 | N17: =L17/F17 -> 0.77883511 | O17: =M17/F17 -> 0.22116489
A18: 2010 | B18: 54 | C18: Yuba River | D18: mark-recapture | E18: fall | F18: ='[2]raw data'!E20 -> 13097 | G18: ='[2]raw data'!F20 -> 789 | H18: =G18/F18 -> 0.060242804 | I18: ='[2]raw data'!H20 -> 341 | J18: =I18/G18 -> 0.43219265 | K18: ='[2]raw data'!I20 -> 330 | L18: =F18-M18 -> 9247.82 | M18: ='[2]raw data'!K20 -> 3849.18 | N18: =L18/F18 -> 0.70610216 | O18: =M18/F18 -> 0.29389784
A19: 2010 | B19: 54 | C19: American River | D19: mark-recapture | E19: fall | F19: ='[2]raw data'!E15 -> 7573 | G19: ='[2]raw data'!F15 -> 1435 | H19: =G19/F19 -> 0.18948897 | I19: ='[2]raw data'!H15 -> 142 | J19: =I19/G19 -> 0.098954704 | K19: ='[2]raw data'!I15 -> 134 | L19: =F19-M19 -> 2438.51 | M19: ='[2]raw data'!K15 -> 5134.49 | N19: =L19/F19 -> 0.32200053 | O19: =M19/F19 -> 0.67799947
A20: 2010 | B20: 59 | C20: Nimbus Weir | D20: actual count | E20: fall | F20: ='[2]raw data'!E27 -> 7115 | G20: ='[2]raw data'!F27 -> 7115 | H20: =G20/F20 -> 1 | I20: ='[2]raw data'!H27 -> 999 | J20: =I20/G20 -> 0.14040759 | K20: ='[2]raw data'!I27 -> 948 | L20: =F20-M20 -> 2684.49 | M20: ='[2]raw data'!K27 -> 4430.51 | N20: =L20/F20 -> 0.37730007 | O20: =M20/F20 -> 0.62269993
E21: Sacramento River basin natural area fall totals | F21: =SUM(F12:F20) -> 96943 | G21: =SUM(G12:G20) -> 17720 | H21: =G21/F21 -> 0.18278782 | I21: =SUM(I12:I20) -> 3025 | J21: =I21/G21 -> 0.17071106 | K21: =SUM(K12:K20) -> 2830 | L21: =SUM(L12:L20) -> 52928.38 | M21: =SUM(M12:M20) -> 44014.62 | N21: =L21/F21 -> 0.54597423 | O21: =M21/F21 -> 0.45402577
A22: SJ natural - fall
A23: year | B23: fishery | C23: Sample site | D23: sample method | E23: sampled run | F23: total estimate | G23: sampled | H23: sample rate | I23: ad-clips obsvd | J23: ad-clip rate | K23: valid CWTs | L23: hatchery component | M23: natural component | N23: hatchery | O23: natural
A24: 2010 | B24: 54 | C24: Mokelume River | D24: video weir | E24: fall | F24: ='[2]raw data'!E24 -> 1920 | G24: ='[2]raw data'!F24 -> 1920 | H24: =G24/F24 -> 1 | I24: ='[2]raw data'!H24 -> 820 | J24: =I24/G24 -> 0.42708333 | K24: ='[2]raw data'!I24 -> 808 | L24: =F24-M24 -> 1409.05 | M24: ='[2]raw data'!K24 -> 510.95 | N24: =L24/F24 -> 0.73388021 | O24: =M24/F24 -> 0.26611979
A25: 2010 | B25: 59 | C25: Mokelumne Weir | D25: actual count | E25: fall | F25: ='[2]raw data'!E28 -> 244 | G25: ='[2]raw data'!F28 -> 244 | H25: =G25/F25 -> 1 | I25: ='[2]raw data'!H28 -> 119 | J25: =I25/G25 -> 0.48770492 | K25: ='[2]raw data'!I28 -> 115 | L25: =F25-M25 -> 180.52 | M25: ='[2]raw data'!K28 -> 63.48 | N25: =L25/F25 -> 0.73983607 | O25: =M25/F25 -> 0.26016393
A26: 2010 | B26: 54 | C26: Merced River | D26: mark-recapture | E26: fall | F26: ='[2]raw data'!E23 -> 651 | G26: ='[2]raw data'!F23 -> 132 | H26: =G26/F26 -> 0.20276498 | I26: ='[2]raw data'!H23 -> 49 | J26: =I26/G26 -> 0.37121212 | K26: ='[2]raw data'!I23 -> 46 | L26: =F26-M26 -> 506.93 | M26: ='[2]raw data'!K23 -> 144.07 | N26: =L26/F26 -> 0.77869432 | O26: =M26/F26 -> 0.22130568
A27: 2010 | B27: 54 | C27: Stanislaus River | D27: mark-recapture | E27: fall | F27: ='[2]raw data'!E25 -> 1086 | G27: ='[2]raw data'!F25 -> 155 | H27: =G27/F27 -> 0.1427256 | I27: ='[2]raw data'!H25 -> 38 | J27: =I27/G27 -> 0.24516129 | K27: ='[2]raw data'!I25 -> 36 | L27: =F27-M27 -> 544.18 | M27: ='[2]raw data'!K25 -> 541.82 | N27: =L27/F27 -> 0.50108656 | O27: =M27/F27 -> 0.49891344
A28: 2010 | B28: 54 | C28: Tuolumne River | D28: mark-recapture | E28: fall | F28: ='[2]raw data'!E26 -> 540 | G28: ='[2]raw data'!F26 -> 85 | H28: =G28/F28 -> 0.15740741 | I28: ='[2]raw data'!H26 -> 27 | J28: =I28/G28 -> 0.31764706 | K28: ='[2]raw data'!I26 -> 24 | L28: =F28-M28 -> 264.26 | M28: ='[2]raw data'!K26 -> 275.74 | N28: =L28/F28 -> 0.48937037 | O28: =M28/F28 -> 0.51062963
E29: San Joaquin basin natural area fall totals | F29: =SUM(F24:F28) -> 4441 | G29: =SUM(G24:G28) -> 2536 | H29: =G29/F29 -> 0.57104256 | I29: =SUM(I24:I28) -> 1053 | J29: =I29/G29 -> 0.41522082 | K29: =SUM(K24:K28) -> 1029 | L29: =SUM(L24:L28) -> 2904.94 | M29: =SUM(M24:M28) -> 1536.06 | N29: =L29/F29 -> 0.65411844 | O29: =M29/F29 -> 0.34588156
A30: CV late fall & spring
A31: year | B31: fishery | C31: Sample site | D31: sample method | E31: sampled run | F31: total estimate | G31: sampled | H31: sample rate | I31: ad-clips obsvd | J31: ad-clip rate | K31: valid CWTs | L31: hatchery component | M31: natural component | N31: hatchery | O31: natural
A32: 2010 | B32: 50 | C32: Coleman Hatchery late fall | D32: actual count | E32: late fall | F32: ='[2]raw data'!E30 -> 5505 | G32: ='[2]raw data'!F30 -> 5505 | H32: =G32/F32 -> 1 | I32: ='[2]raw data'!H30 -> 5391 | J32: =I32/G32 -> 0.97929155 | K32: ='[2]raw data'!I30 -> 5258 | L32: =F32-M32 -> 5478.13 | M32: ='[2]raw data'!K30 -> 26.87
A33: 2010 | B33: 54 | C33: American River late fall count | D33: cumulative cnt | E33: late fall | F33: ='[2]raw data'!E31 -> 162 | G33: ='[2]raw data'!F31 -> 162 | H33: =G33/F33 -> 1 | I33: ='[2]raw data'!H31 -> 37 | J33: =I33/G33 -> 0.22839506 | K33: ='[2]raw data'!I31 -> 37 | L33: =F33-M33 -> 38.61 | M33: ='[2]raw data'!K31 -> 123.39 | N33: =L33/F33 -> 0.23833333 | O33: =M33/F33 -> 0.76166667
A34: 2010 | B34: 54 | C34: Upper Sac late fall carcass | D34: mark-recapture | E34: late fall | F34: ='[2]raw data'!E32 -> 4282 | G34: ='[2]raw data'!F32 -> 811 | H34: =G34/F34 -> 0.18939748 | I34: ='[2]raw data'!H32 -> 47 | J34: =I34/G34 -> 0.057953144 | K34: ='[2]raw data'!I32 -> 43 | L34: =F34-M34 -> 249.73 | M34: ='[2]raw data'!K32 -> 4032.27 | N34: =L34/F34 -> 0.058320878 | O34: =M34/F34 -> 0.94167912
A35: 2010 | B35: 54 | C35: Butte Crk spring carcass | D35: mark-recapture | E35: spring | F35: ='[2]raw data'!E4 -> 1979 | G35: ='[2]raw data'!F4 -> 1113 | H35: =G35/F35 -> 0.56240526 | I35: ='[2]raw data'!H4 -> 21 | J35: =I35/G35 -> 0.018867925 | K35: ='[2]raw data'!I4 -> 16 | L35: =F35-M35 -> 29.14 | M35: ='[2]raw data'!K4 -> 1949.86 | N35: =L35/F35 -> 0.014724608 | O35: =M35/F35 -> 0.98527539
A36: 2010 | B36: 54 | C36: Mill Crk spring | D36: redd count | E36: spring | F36: ='[2]raw data'!E5 -> 482 | G36: ='[2]raw data'!F5 -> 482 | H36: =G36/F36 -> 1 | I36: ='[2]raw data'!H5 -> 1 | J36: =I36/G36 -> 0.0020746888 | K36: ='[2]raw data'!I5 -> 1 | L36: =F36-M36 -> 1.03 | M36: ='[2]raw data'!K5 -> 480.97 | N36: =L36/F36 -> 0.0021369295 | O36: =M36/F36 -> 0.99786307
A37: 2010 | B37: 54 | C37: Deek Crk spring | D37: snorkle-max cnt | E37: spring | F37: 262 | G37: 262 | H37: =G37/F37 -> 1 | M37: 262 | O37: =M37/F37 -> 1
A38: 2010 | B38: 50 | C38: Feather R Hatchery spring | D38: actual count | E38: spring | F38: ='[2]raw data'!E3 -> 1661 | G38: ='[2]raw data'!F3 -> 1661 | H38: =G38/F38 -> 1 | I38: ='[2]raw data'!H3 -> 1279 | J38: =I38/G38 -> 0.77001806 | K38: ='[2]raw data'!I3 -> 1234 | L38: =F38-M38 -> 1361.01 | M38: ='[2]raw data'!K3 -> 299.99 | N38: =L38/F38 -> 0.81939193 | O38: =M38/F38 -> 0.18060807
E39: Sacramento River basin late fall and spring totals | F39: =SUM(F32:F38) -> 14333 | G39: =SUM(G32:G38) -> 9996 | H39: =G39/F39 -> 0.69741157 | I39: =SUM(I32:I38) -> 6776 | J39: =I39/G39 -> 0.67787115 | K39: =SUM(K32:K38) -> 6589 | L39: =SUM(L32:L38) -> 7157.65 | M39: =SUM(M32:M38) -> 7175.35 | N39: =L39/F39 -> 0.49938254 | O39: =M39/F39 -> 0.50061746
A41: CV creel survey
...

Sheet Table 7 Inland 2011 Tag Summary
A1: Table 7. Raw and expanded CV Chinook CWT recoveries by stock and age, brood years 2006-2011.
B3: Fall | C3: =D3+1 -> 2010 | D3: =E3+1 -> 2009 | E3: =F3+1 -> 2008 | F3: =G3+1 -> 2007 | G3: 2006 | J3: Total CV CWTs | K3: Total CV %
B4: Age | C4: 1 | D4: 2 | E4: 3 | F4: 4 | G4: 5
A6: Raw CWT Recoveries | C6: ='[1]raw inland'!L5 -> 3 | D6: ='[1]raw inland'!M5 -> 27506 | E6: ='[1]raw inland'!N5 -> 9053 | F6: ='[1]raw inland'!O5 -> 1381 | G6: ='[1]raw inland'!P5 -> 1 | J6: =SUM(C6:G6) -> 37944 | K6: =J6/$J$41 -> 0.81431883
C7: (< 1%) | D7: (72%) | E7: (24%) | F7: (4%) | G7: (< 1%)
A9: Expanded CWTtotal | C9: ='[1]raw inland'!L7 -> 46.56 | D9: 121939 | E9: 76753 | F9: 13412 | G9: ='[1]raw inland'!P7 -> 4.29 | J9: =SUM(C9:G9) -> 212154.85 | K9: =J9/$J$44 -> 0.9317283
C10: (< 1%) | D10: (57%) | E10: (36%) | F10: (6%) | G10: (< 1%)
B12: Spring | C12: =C3 -> 2010 | D12: =D3 -> 2009 | E12: =E3 -> 2008 | F12: =F3 -> 2007 | G12: =G3 -> 2006 | J12: Total CV CWTs | K12: Total CV %
B13: Age | C13: 1 | D13: 2 | E13: 3 | F13: 4 | G13: 5
A15: Raw CWT Recoveries | D15: ='[1]raw inland'!M12 -> 1317 | E15: ='[1]raw inland'!N12 -> 2125 | F15: ='[1]raw inland'!O12 -> 540 | J15: =SUM(C15:G15) -> 3982 | K15: =J15/$J$41 -> 0.085457979
D16: (33%) | E16: (54%) | F16: (14%)
A18: Expanded CWTtotal | D18: ='[1]raw inland'!M14 -> 1880.02 | E18: ='[1]raw inland'!N14 -> 4421.48 | F18: ='[1]raw inland'!O14 -> 1541.17 | J18: =SUM(C18:G18) -> 7842.67 | K18: =J18/$J$44 -> 0.034442944
D19: (24%) | E19: (56%) | F19: (20%)
B21: Late-Fall | C21: =D21+1 -> 2011 | D21: =E21+1 -> 2010 | E21: =F21+1 -> 2009 | F21: =G21+1 -> 2008 | G21: =H21+1 -> 2007 | H21: 2006 | J21: Total CV CWTs | K21: Total CV %
B22: Age | C22: 1 | D22: 2 | E22: 3 | F22: 4 | G22: 5 | H22: 6
A24: Raw CWT Recoveries | D24: ='[1]raw inland'!M26 -> 102 | E24: ='[1]raw inland'!N26 -> 1077 | F24: ='[1]raw inland'!O26 -> 2974 | G24: ='[1]raw inland'!P26 -> 511 | H24: ='[1]raw inland'!Q26 -> 4 | J24: =SUM(D24:H24) -> 4668 | K24: =J24/$J$41 -> 0.10018027
D25: (2%) | E25: (23%) | F25: (64%) | G25: (11%) | H25: (< 1%)
A27: Expanded CWTtotal | D27: ='[1]raw inland'!M28 -> 374.58 | E27: ='[1]raw inland'!N28 -> 2273.05 | F27: ='[1]raw inland'!O28 -> 3941.37 | G27: ='[1]raw inland'!P28 -> 1104.16 | H27: ='[1]raw inland'!Q28 -> 4.46 | J27: =SUM(D27:H27) -> 7697.62 | K27: =J27/$J$44 -> 0.033805922
D28: (5%) | E28: (30%) | F28: (51%) | G28: (14%) | H28: (< 1%)
B30: Winter | C30: =D30+1 -> 2011 | D30: =E30+1 -> 2010 | E30: =F30+1 -> 2009 | F30: =G30+1 -> 2008 | G30: =H30+1 -> 2007 | H30: =H21 -> 2006 | J30: Total CV CWTs | K30: Total CV %
B31: Age | C31: 1 | D31: 2 | E31: 3 | F31: 4 | G31: 5 | H31: 6
A33: Raw CWT Recoveries | D33: ='[1]raw inland'!M19 -> 1 | E33: ='[1]raw inland'!N19 -> 1 | J33: =SUM(D33:H33) -> 2 | K33: =J33/$J$41 -> 4.2922139e-05
D34: (50%) | E34: (50%)
A36: Expanded CWTtotal | D36: ='[1]raw inland'!M21 -> 2.08 | E36: ='[1]raw inland'!N21 -> 2.12 | J36: =SUM(D36:H36) -> 4.2 | K36: =J36/$J$44 -> 1.8445295e-05
D37: (50%) | E37: (50%)
B38: All Runs | J38: Total CV CWTs | K38: Total CV %
B39: Age | C39: 1 | D39: 2 | E39: 3 | F39: 4 | G39: 5 | H39: 6
A41: Raw CWT Recoveries | C41: =C33+C24+C15+C6 -> 3 | D41: =D33+D24+D15+D6 -> 28926 | E41: =E33+E24+E15+E6 -> 12256 | F41: =F33+F24+F15+F6 -> 4895 | G41: =G33+G24+G15+G6 -> 512 | H41: =H33+H24+H15+H6 -> 4 | J41: =SUM(C41:I41) -> 46596 | K41: =K33+K24+K15+K6 -> 1
C42: (< 1%) | D42: (62%) | E42: (26%) | F42: (11%) | G42: (1%) | H42: (< 1%)
A44: Expanded CWTtotal | C44: =C9+C18+C27+C36 -> 46.56 | D44: =D9+D18+D27+D36 -> 124195.68 | E44: =E9+E18+E27+E36 -> 83449.65 | F44: =F9+F18+F27+F36 -> 18894.54 | G44: =G9+G18+G27+G36 -> 1108.45 | H44: =H9+H18+H27+H36 -> 4.46 | J44: =SUM(C44:H44)+1 -> 227700.34 | K44: =K36+K27+K18+K9 -> 0.99999561
C45: (< 1%) | D45: (54%) | E45: (37%) | F45: (8%) | G45: (< 1%) | H45: (< 1%)
D46: `

Sheet 2011 Table 9
A1: Table 9. Percentage of inland CWTtotal recoveries by location, run, and release typeᵃ in hatchery returns, natural escapement and sport harvest during 2011.
E3: Coleman National Fish Hatchery | J3: Feather River Hatcheryᵇ | R3: Nimbus Hatchery | U3: Mokelumne/Merced hatcheriesᵇ | AA3: Total % | AC3: Total
A4: Location | B4: location | C4: fishery | D4: Run | E4: CFHLh | F4: CFHLe | G4: CFHFh | H4: CFHFn | I4: CFHFe | J4: FRHS | K4: FRHSn | L4: FRHFe | M4: FRHFn | N4: FRHFnc | O4: FRHFt | P4: FRHFtib | Q4: FEAFw | R4: NIMF | S4: NIMFn | T4: NIMFtib | U4: MOKF | V4: MOKFn | W4: MOKFt | X4: MokFw | Y4: MERF | Z4: nonCV | AA4: Hatchery | AB4: Natural | AC4: Run
A6: Hatchery Spawners
A7: Coleman Hatchery | B7: CNFH | C7: 50 | D7: Late | E7: =IF('[3]actual CWTs exp'!E4/'[3]actual CWTs exp'!$AC4>0.0005,'[3]actual CWTs exp'!E4/'[3]actual CWTs exp'!$AC4,IF('[3]actual CWTs exp'!E4/'[3]actual CWTs exp'!$AC4>0,"* "," ")) -> 0.98434054 | F7: =IF('[3]actual CWTs exp'!F4/'[3]actual CWTs exp'!$AC4>0.0005,'[3]actual CWTs exp'!F4/'[3]actual CWTs exp'!$AC4,IF('[3]actual CWTs exp'!F4/'[3]actual CWTs exp'!$AC4>0,"- "," ")) -> - | G7: =IF('[3]actual CWTs exp'!G4/'[3]actual CWTs exp'!$AC4>0.0005,'[3]actual CWTs exp'!G4/'[3]actual CWTs exp'!$AC4,IF('[3]actual CWTs exp'!G4/'[3]actual CWTs exp'!$AC4>0,"- "," ")) -> 0.020291134 | H7: =IF('[3]actual CWTs exp'!H4/'[3]actual CWTs exp'!$AC4>0.0005,'[3]actual CWTs exp'!H4/'[3]actual CWTs exp'!$AC4,IF('[3]actual CWTs exp'!H4/'[3]actual CWTs exp'!$AC4>0,"- "," ")) -> 0.0008822232 | I7: =IF('[3]actual CWTs exp'!I4/'[3]actual CWTs exp'!$AC4>0.0005,'[3]actual CWTs exp'!I4/'[3]actual CWTs exp'!$AC4,IF('[3]actual CWTs exp'!I4/'[3]actual CWTs exp'!$AC4>0,"- "," ")) | J7: =IF('[3]actual CWTs exp'!J4/'[3]actual CWTs exp'!$AC4>0.0005,'[3]actual CWTs exp'!J4/'[3]actual CWTs exp'!$AC4,IF('[3]actual CWTs exp'!J4/'[3]actual CWTs exp'!$AC4>0,"- "," ")) | K7: =IF('[3]actual CWTs exp'!K4/'[3]actual CWTs exp'!$AC4>0.0005,'[3]actual CWTs exp'!K4/'[3]actual CWTs exp'!$AC4,IF('[3]actual CWTs exp'!K4/'[3]actual CWTs exp'!$AC4>0,"- "," ")) | L7: =IF('[3]actual CWTs exp'!L4/'[3]actual CWTs exp'!$AC4>0.0005,'[3]actual CWTs exp'!L4/'[3]actual CWTs exp'!$AC4,IF('[3]actual CWTs exp'!L4/'[3]actual CWTs exp'!$AC4>0,"- "," ")) | M7: =IF('[3]actual CWTs exp'!M4/'[3]actual CWTs exp'!$AC4>0.0005,'[3]actual CWTs exp'!M4/'[3]actual CWTs exp'!$AC4,IF('[3]actual CWTs exp'!M4/'[3]actual CWTs exp'!$AC4>0,"- "," ")) | ... Z7: =IF('[3]actual CWTs exp'!Z4/'[3]actual CWTs exp'!$AC4>0.0005,'[3]actual CWTs exp'!Z4/'[3]actual CWTs exp'!$AC4,IF('[3]actual CWTs exp'!Z4/'[3]actual CWTs exp'!$AC4>0,"- "," ")) | AA7: 1 | AB7: 1e-06 | AC7: ='[3]actual CWTs exp'!AC4 -> 4534
A8: Feather River Hatchery | B8: FRFH | C8: 50 | D8: Spring | E8: =IF('[3]actual CWTs exp'!E5/'[3]actual CWTs exp'!$AC5>0.0005,'[3]actual CWTs exp'!E5/'[3]actual CWTs exp'!$AC5,IF('[3]actual CWTs exp'!E5/'[3]actual CWTs exp'!$AC5>0,"- "," ")) | F8: =IF('[3]actual CWTs exp'!F5/'[3]actual CWTs exp'!$AC5>0.0005,'[3]actual CWTs exp'!F5/'[3]actual CWTs exp'!$AC5,IF('[3]actual CWTs exp'!F5/'[3]actual CWTs exp'!$AC5>0,"- "," ")) | G8: =IF('[3]actual CWTs exp'!G5/'[3]actual CWTs exp'!$AC5>0.0005,'[3]actual CWTs exp'!G5/'[3]actual CWTs exp'!$AC5,IF('[3]actual CWTs exp'!G5/'[3]actual CWTs exp'!$AC5>0,"- "," ")) | H8: =IF('[3]actual CWTs exp'!H5/'[3]actual CWTs exp'!$AC5>0.0005,'[3]actual CWTs exp'!H5/'[3]actual CWTs exp'!$AC5,IF('[3]actual CWTs exp'!H5/'[3]actual CWTs exp'!$AC5>0,"- "," ")) | I8: =IF('[3]actual CWTs exp'!I5/'[3]actual CWTs exp'!$AC5>0.0005,'[3]actual CWTs exp'!I5/'[3]actual CWTs exp'!$AC5,IF('[3]actual CWTs exp'!I5/'[3]actual CWTs exp'!$AC5>0,"- "," ")) | J8: =IF('[3]actual CWTs exp'!J5/'[3]actual CWTs exp'!$AC5>0.0005,'[3]actual CWTs exp'!J5/'[3]actual CWTs exp'!$AC5,IF('[3]actual CWTs exp'!J5/'[3]actual CWTs exp'!$AC5>0,"- "," ")) -> 0.24225495 | K8: =IF('[3]actual CWTs exp'!K5/'[3]actual CWTs exp'!$AC5>0.0005,'[3]actual CWTs exp'!K5/'[3]actual CWTs exp'!$AC5,IF('[3]actual CWTs exp'!K5/'[3]actual CWTs exp'!$AC5>0,"- "," ")) -> 0.29507364 | L8: =IF('[3]actual CWTs exp'!L5/'[3]actual CWTs exp'!$AC5>0.0005,'[3]actual CWTs exp'!L5/'[3]actual CWTs exp'!$AC5,IF('[3]actual CWTs exp'!L5/'[3]actual CWTs exp'!$AC5>0,"- "," ")) -> 0.064499746 | ... Z8: =IF('[3]actual CWTs exp'!Z5/'[3]actual CWTs exp'!$AC5>0.0005,'[3]actual CWTs exp'!Z5/'[3]actual CWTs exp'!$AC5,IF('[3]actual CWTs exp'!Z5/'[3]actual CWTs exp'!$AC5>0,"- "," ")) | AA8: =SUM(E8:Z8) -> 0.936516 | AB8: =1-AA8 -> 0.063484002 | AC8: ='[3]actual CWTs exp'!AC5 -> 1969
A9: Coleman Hatchery | B9: CNFH | C9: 50 | D9: Fall | E9: =IF('[3]actual CWTs exp'!E6/'[3]actual CWTs exp'!$AC6>0.0005,'[3]actual CWTs exp'!E6/'[3]actual CWTs exp'!$AC6,IF('[3]actual CWTs exp'!E6/'[3]actual CWTs exp'!$AC6>0,"- "," ")) -> 0.0064889099 | F9: =IF('[3]actual CWTs exp'!F6/'[3]actual CWTs exp'!$AC6>0.0005,'[3]actual CWTs exp'!F6/'[3]actual CWTs exp'!$AC6,IF('[3]actual CWTs exp'!F6/'[3]actual CWTs exp'!$AC6>0,"- "," ")) | G9: =IF('[3]actual CWTs exp'!G6/'[3]actual CWTs exp'!$AC6>0.0005,'[3]actual CWTs exp'!G6/'[3]actual CWTs exp'!$AC6,IF('[3]actual CWTs exp'!G6/'[3]actual CWTs exp'!$AC6>0,"- "," ")) -> 0.86774422 | H9: =IF('[3]actual CWTs exp'!H6/'[3]actual CWTs exp'!$AC6>0.0005,'[3]actual CWTs exp'!H6/'[3]actual CWTs exp'!$AC6,IF('[3]actual CWTs exp'!H6/'[3]actual CWTs exp'!$AC6>0,"- "," ")) -> 0.0052147239 | I9: =IF('[3]actual CWTs exp'!I6/'[3]actual CWTs exp'!$AC6>0.0005,'[3]actual CWTs exp'!I6/'[3]actual CWTs exp'!$AC6,IF('[3]actual CWTs exp'!I6/'[3]actual CWTs exp'!$AC6>0,"- "," ")) -> - | J9: =IF('[3]actual CWTs exp'!J6/'[3]actual CWTs exp'!$AC6>0.0005,'[3]actual CWTs exp'!J6/'[3]actual CWTs exp'!$AC6,IF('[3]actual CWTs exp'!J6/'[3]actual CWTs exp'!$AC6>0,"- "," ")) | K9: =IF('[3]actual CWTs exp'!K6/'[3]actual CWTs exp'!$AC6>0.0005,'[3]actual CWTs exp'!K6/'[3]actual CWTs exp'!$AC6,IF('[3]actual CWTs exp'!K6/'[3]actual CWTs exp'!$AC6>0,"- "," ")) | L9: =IF('[3]actual CWTs exp'!L6/'[3]actual CWTs exp'!$AC6>0.0005,'[3]actual CWTs exp'!L6/'[3]actual CWTs exp'!$AC6,IF('[3]actual CWTs exp'!L6/'[3]actual CWTs exp'!$AC6>0,"- "," ")) -> - | ... Z9: =IF('[3]actual CWTs exp'!Z6/'[3]actual CWTs exp'!$AC6>0.0005,'[3]actual CWTs exp'!Z6/'[3]actual CWTs exp'!$AC6,IF('[3]actual CWTs exp'!Z6/'[3]actual CWTs exp'!$AC6>0,"- "," ")) | AA9: =SUM(E9:Z9) -> 0.88560642 | AB9: =1-AA9 -> 0.11439358 | AC9: ='[3]actual CWTs exp'!AC6 -> 42380
A10: Feather River Hatchery | B10: FRFH | C10: 50 | D10: Fall | E10: =IF('[3]actual CWTs exp'!E7/'[3]actual CWTs exp'!$AC7>0.0005,'[3]actual CWTs exp'!E7/'[3]actual CWTs exp'!$AC7,IF('[3]actual CWTs exp'!E7/'[3]actual CWTs exp'!$AC7>0,"- "," ")) | F10: =IF('[3]actual CWTs exp'!F7/'[3]actual CWTs exp'!$AC7>0.0005,'[3]actual CWTs exp'!F7/'[3]actual CWTs exp'!$AC7,IF('[3]actual CWTs exp'!F7/'[3]actual CWTs exp'!$AC7>0,"- "," ")) | G10: =IF('[3]actual CWTs exp'!G7/'[3]actual CWTs exp'!$AC7>0.0005,'[3]actual CWTs exp'!G7/'[3]actual CWTs exp'!$AC7,IF('[3]actual CWTs exp'!G7/'[3]actual CWTs exp'!$AC7>0,"- "," ")) -> - | H10: =IF('[3]actual CWTs exp'!H7/'[3]actual CWTs exp'!$AC7>0.0005,'[3]actual CWTs exp'!H7/'[3]actual CWTs exp'!$AC7,IF('[3]actual CWTs exp'!H7/'[3]actual CWTs exp'!$AC7>0,"- "," ")) -> 0.025600932 | I10: =IF('[3]actual CWTs exp'!I7/'[3]actual CWTs exp'!$AC7>0.0005,'[3]actual CWTs exp'!I7/'[3]actual CWTs exp'!$AC7,IF('[3]actual CWTs exp'!I7/'[3]actual CWTs exp'!$AC7>0,"- "," ")) -> - | J10: =IF('[3]actual CWTs exp'!J7/'[3]actual CWTs exp'!$AC7>0.0005,'[3]actual CWTs exp'!J7/'[3]actual CWTs exp'!$AC7,IF('[3]actual CWTs exp'!J7/'[3]actual CWTs exp'!$AC7>0,"- "," ")) -> 0.032683346 | K10: =IF('[3]actual CWTs exp'!K7/'[3]actual CWTs exp'!$AC7>0.0005,'[3]actual CWTs exp'!K7/'[3]actual CWTs exp'!$AC7,IF('[3]actual CWTs exp'!K7/'[3]actual CWTs exp'!$AC7>0,"- "," ")) -> 0.040041697 | L10: =IF('[3]actual CWTs exp'!L7/'[3]actual CWTs exp'!$AC7>0.0005,'[3]actual CWTs exp'!L7/'[3]actual CWTs exp'!$AC7,IF('[3]actual CWTs exp'!L7/'[3]actual CWTs exp'!$AC7>0,"- "," ")) -> 0.016188374 | ... Z10: =IF('[3]actual CWTs exp'!Z7/'[3]actual CWTs exp'!$AC7>0.0005,'[3]actual CWTs exp'!Z7/'[3]actual CWTs exp'!$AC7,IF('[3]actual CWTs exp'!Z7/'[3]actual CWTs exp'!$AC7>0,"- "," ")) | AA10: =SUM(E10:Z10) -> 0.95750552 | AB10: =1-AA10 -> 0.042494481 | AC10: ='[3]actual CWTs exp'!AC7 -> 32616
A11: Nimbus Hatchery | B11: NBFH | C11: 50 | D11: Fall | E11: =IF('[3]actual CWTs exp'!E8/'[3]actual CWTs exp'!$AC8>0.0005,'[3]actual CWTs exp'!E8/'[3]actual CWTs exp'!$AC8,IF('[3]actual CWTs exp'!E8/'[3]actual CWTs exp'!$AC8>0,"- "," ")) | F11: =IF('[3]actual CWTs exp'!F8/'[3]actual CWTs exp'!$AC8>0.0005,'[3]actual CWTs exp'!F8/'[3]actual CWTs exp'!$AC8,IF('[3]actual CWTs exp'!F8/'[3]actual CWTs exp'!$AC8>0,"- "," ")) | G11: =IF('[3]actual CWTs exp'!G8/'[3]actual CWTs exp'!$AC8>0.0005,'[3]actual CWTs exp'!G8/'[3]actual CWTs exp'!$AC8,IF('[3]actual CWTs exp'!G8/'[3]actual CWTs exp'!$AC8>0,"- "," ")) | H11: =IF('[3]actual CWTs exp'!H8/'[3]actual CWTs exp'!$AC8>0.0005,'[3]actual CWTs exp'!H8/'[3]actual CWTs exp'!$AC8,IF('[3]actual CWTs exp'!H8/'[3]actual CWTs exp'!$AC8>0,"- "," ")) -> 0.019716088 | I11: =IF('[3]actual CWTs exp'!I8/'[3]actual CWTs exp'!$AC8>0.0005,'[3]actual CWTs exp'!I8/'[3]actual CWTs exp'!$AC8,IF('[3]actual CWTs exp'!I8/'[3]actual CWTs exp'!$AC8>0,"- "," ")) | J11: =IF('[3]actual CWTs exp'!J8/'[3]actual CWTs exp'!$AC8>0.0005,'[3]actual CWTs exp'!J8/'[3]actual CWTs exp'!$AC8,IF('[3]actual CWTs exp'!J8/'[3]actual CWTs exp'!$AC8>0,"- "," ")) | K11: =IF('[3]actual CWTs exp'!K8/'[3]actual CWTs exp'!$AC8>0.0005,'[3]actual CWTs exp'!K8/'[3]actual CWTs exp'!$AC8,IF('[3]actual CWTs exp'!K8/'[3]actual CWTs exp'!$AC8>0,"- "," ")) | L11: =IF('[3]actual CWTs exp'!L8/'[3]actual CWTs exp'!$AC8>0.0005,'[3]actual CWTs exp'!L8/'[3]actual CWTs exp'!$AC8,IF('[3]actual CWTs exp'!L8/'[3]actual CWTs exp'!$AC8>0,"- "," ")) -> - | ... Z11: =IF('[3]actual CWTs exp'!Z8/'[3]actual CWTs exp'!$AC8>0.0005,'[3]actual CWTs exp'!Z8/'[3]actual CWTs exp'!$AC8,IF('[3]actual CWTs exp'!Z8/'[3]actual CWTs exp'!$AC8>0,"- "," ")) | AA11: =SUM(E11:Z11) -> 0.76884858 | AB11: =1-AA11 -> 0.23115142 | AC11: ='[3]actual CWTs exp'!AC8 -> 12680
A12: Nimbus Weir | B12: NIMW | C12: 50 | D12: Fall | E12: =IF('[3]actual CWTs exp'!E9/'[3]actual CWTs exp'!$AC9>0.0005,'[3]actual CWTs exp'!E9/'[3]actual CWTs exp'!$AC9,IF('[3]actual CWTs exp'!E9/'[3]actual CWTs exp'!$AC9>0,"- "," ")) | F12: =IF('[3]actual CWTs exp'!F9/'[3]actual CWTs exp'!$AC9>0.0005,'[3]actual CWTs exp'!F9/'[3]actual CWTs exp'!$AC9,IF('[3]actual CWTs exp'!F9/'[3]actual CWTs exp'!$AC9>0,"- "," ")) | G12: =IF('[3]actual CWTs exp'!G9/'[3]actual CWTs exp'!$AC9>0.0005,'[3]actual CWTs exp'!G9/'[3]actual CWTs exp'!$AC9,IF('[3]actual CWTs exp'!G9/'[3]actual CWTs exp'!$AC9>0,"- "," ")) | H12: =IF('[3]actual CWTs exp'!H9/'[3]actual CWTs exp'!$AC9>0.0005,'[3]actual CWTs exp'!H9/'[3]actual CWTs exp'!$AC9,IF('[3]actual CWTs exp'!H9/'[3]actual CWTs exp'!$AC9>0,"- "," ")) -> 0.032933367 | I12: =IF('[3]actual CWTs exp'!I9/'[3]actual CWTs exp'!$AC9>0.0005,'[3]actual CWTs exp'!I9/'[3]actual CWTs exp'!$AC9,IF('[3]actual CWTs exp'!I9/'[3]actual CWTs exp'!$AC9>0,"- "," ")) | J12: =IF('[3]actual CWTs exp'!J9/'[3]actual CWTs exp'!$AC9>0.0005,'[3]actual CWTs exp'!J9/'[3]actual CWTs exp'!$AC9,IF('[3]actual CWTs exp'!J9/'[3]actual CWTs exp'!$AC9>0,"- "," ")) | K12: =IF('[3]actual CWTs exp'!K9/'[3]actual CWTs exp'!$AC9>0.0005,'[3]actual CWTs exp'!K9/'[3]actual CWTs exp'!$AC9,IF('[3]actual CWTs exp'!K9/'[3]actual CWTs exp'!$AC9>0,"- "," ")) -> 0.001787082 | L12: =IF('[3]actual CWTs exp'!L9/'[3]actual CWTs exp'!$AC9>0.0005,'[3]actual CWTs exp'!L9/'[3]actual CWTs exp'!$AC9,IF('[3]actual CWTs exp'!L9/'[3]actual CWTs exp'!$AC9>0,"- "," ")) -> 0.00076589226 | ... Z12: =IF('[3]actual CWTs exp'!Z9/'[3]actual CWTs exp'!$AC9>0.0005,'[3]actual CWTs exp'!Z9/'[3]actual CWTs exp'!$AC9,IF('[3]actual CWTs exp'!Z9/'[3]actual CWTs exp'!$AC9>0,"- "," ")) | AA12: =SUM(E12:Z12) -> 0.2570845 | AB12: =1-AA12 -> 0.7429155 | AC12: ='[3]actual CWTs exp'!AC9 -> 3917
A13: Mokelumne Hatchery | B13: MRFI | C13: 50 | D13: Fall | E13: =IF('[3]actual CWTs exp'!E10/'[3]actual CWTs exp'!$AC10>0.0005,'[3]actual CWTs exp'!E10/'[3]actual CWTs exp'!$AC10,IF('[3]actual CWTs exp'!E10/'[3]actual CWTs exp'!$AC10>0,"- "," ")) -> - | F13: =IF('[3]actual CWTs exp'!F10/'[3]actual CWTs exp'!$AC10>0.0005,'[3]actual CWTs exp'!F10/'[3]actual CWTs exp'!$AC10,IF('[3]actual CWTs exp'!F10/'[3]actual CWTs exp'!$AC10>0,"- "," ")) | G13: =IF('[3]actual CWTs exp'!G10/'[3]actual CWTs exp'!$AC10>0.0005,'[3]actual CWTs exp'!G10/'[3]actual CWTs exp'!$AC10,IF('[3]actual CWTs exp'!G10/'[3]actual CWTs exp'!$AC10>0,"- "," ")) -> - | H13: =IF('[3]actual CWTs exp'!H10/'[3]actual CWTs exp'!$AC10>0.0005,'[3]actual CWTs exp'!H10/'[3]actual CWTs exp'!$AC10,IF('[3]actual CWTs exp'!H10/'[3]actual CWTs exp'!$AC10>0,"- "," ")) -> 0.025185278 | I13: =IF('[3]actual CWTs exp'!I10/'[3]actual CWTs exp'!$AC10>0.0005,'[3]actual CWTs exp'!I10/'[3]actual CWTs exp'!$AC10,IF('[3]actual CWTs exp'!I10/'[3]actual CWTs exp'!$AC10>0,"- "," ")) | J13: =IF('[3]actual CWTs exp'!J10/'[3]actual CWTs exp'!$AC10>0.0005,'[3]actual CWTs exp'!J10/'[3]actual CWTs exp'!$AC10,IF('[3]actual CWTs exp'!J10/'[3]actual CWTs exp'!$AC10>0,"- "," ")) -> - | K13: =IF('[3]actual CWTs exp'!K10/'[3]actual CWTs exp'!$AC10>0.0005,'[3]actual CWTs exp'!K10/'[3]actual CWTs exp'!$AC10,IF('[3]actual CWTs exp'!K10/'[3]actual CWTs exp'!$AC10>0,"- "," ")) -> 0.00081648034 | L13: =IF('[3]actual CWTs exp'!L10/'[3]actual CWTs exp'!$AC10>0.0005,'[3]actual CWTs exp'!L10/'[3]actual CWTs exp'!$AC10,IF('[3]actual CWTs exp'!L10/'[3]actual CWTs exp'!$AC10>0,"- "," ")) -> - | ... Z13: =IF('[3]actual CWTs exp'!Z10/'[3]actual CWTs exp'!$AC10>0.0005,'[3]actual CWTs exp'!Z10/'[3]actual CWTs exp'!$AC10,IF('[3]actual CWTs exp'!Z10/'[3]actual CWTs exp'!$AC10>0,"- "," ")) | AA13: =SUM(E13:Z13) -> 0.97682452 | AB13: =1-AA13 -> 0.02317548 | AC13: ='[3]actual CWTs exp'!AC10 -> 15922
A14: Merced Hatchery | B14: MRFF | C14: 50 | D14: Fall | E14: =IF('[3]actual CWTs exp'!E11/'[3]actual CWTs exp'!$AC11>0.0005,'[3]actual CWTs exp'!E11/'[3]actual CWTs exp'!$AC11,IF('[3]actual CWTs exp'!E11/'[3]actual CWTs exp'!$AC11>0,"- "," ")) -> 0.0022883295 | F14: =IF('[3]actual CWTs exp'!F11/'[3]actual CWTs exp'!$AC11>0.0005,'[3]actual CWTs exp'!F11/'[3]actual CWTs exp'!$AC11,IF('[3]actual CWTs exp'!F11/'[3]actual CWTs exp'!$AC11>0,"- "," ")) | G14: =IF('[3]actual CWTs exp'!G11/'[3]actual CWTs exp'!$AC11>0.0005,'[3]actual CWTs exp'!G11/'[3]actual CWTs exp'!$AC11,IF('[3]actual CWTs exp'!G11/'[3]actual CWTs exp'!$AC11>0,"- "," ")) | H14: =IF('[3]actual CWTs exp'!H11/'[3]actual CWTs exp'!$AC11>0.0005,'[3]actual CWTs exp'!H11/'[3]actual CWTs exp'!$AC11,IF('[3]actual CWTs exp'!H11/'[3]actual CWTs exp'!$AC11>0,"- "," ")) -> 0.036613272 | I14: =IF('[3]actual CWTs exp'!I11/'[3]actual CWTs exp'!$AC11>0.0005,'[3]actual CWTs exp'!I11/'[3]actual CWTs exp'!$AC11,IF('[3]actual CWTs exp'!I11/'[3]actual CWTs exp'!$AC11>0,"- "," ")) | J14: =IF('[3]actual CWTs exp'!J11/'[3]actual CWTs exp'!$AC11>0.0005,'[3]actual CWTs exp'!J11/'[3]actual CWTs exp'!$AC11,IF('[3]actual CWTs exp'!J11/'[3]actual CWTs exp'!$AC11>0,"- "," ")) | K14: =IF('[3]actual CWTs exp'!K11/'[3]actual CWTs exp'!$AC11>0.0005,'[3]actual CWTs exp'!K11/'[3]actual CWTs exp'!$AC11,IF('[3]actual CWTs exp'!K11/'[3]actual CWTs exp'!$AC11>0,"- "," ")) | L14: =IF('[3]actual CWTs exp'!L11/'[3]actual CWTs exp'!$AC11>0.0005,'[3]actual CWTs exp'!L11/'[3]actual CWTs exp'!$AC11,IF('[3]actual CWTs exp'!L11/'[3]actual CWTs exp'!$AC11>0,"- "," ")) | ... Z14: =IF('[3]actual CWTs exp'!Z11/'[3]actual CWTs exp'!$AC11>0.0005,'[3]actual CWTs exp'!Z11/'[3]actual CWTs exp'!$AC11,IF('[3]actual CWTs exp'!Z11/'[3]actual CWTs exp'!$AC11>0,"- "," ")) | AA14: =SUM(E14:Z14) -> 0.87871854 | AB14: =1-AA14 -> 0.12128146 | AC14: ='[3]actual CWTs exp'!AC11 -> 437
A15: Total Hatchery Fall Run | E15: =IF('[3]actual CWTs exp'!E12/'[3]actual CWTs exp'!$AC12>0.0005,'[3]actual CWTs exp'!E12/'[3]actual CWTs exp'!$AC12,IF('[3]actual CWTs exp'!E12/'[3]actual CWTs exp'!$AC12>0,"- "," ")) -> 0.0025659552 | F15: =IF('[3]actual CWTs exp'!F12/'[3]actual CWTs exp'!$AC12>0.0005,'[3]actual CWTs exp'!F12/'[3]actual CWTs exp'!$AC12,IF('[3]actual CWTs exp'!F12/'[3]actual CWTs exp'!$AC12>0,"- "," ")) | G15: =IF('[3]actual CWTs exp'!G12/'[3]actual CWTs exp'!$AC12>0.0005,'[3]actual CWTs exp'!G12/'[3]actual CWTs exp'!$AC12,IF('[3]actual CWTs exp'!G12/'[3]actual CWTs exp'!$AC12>0,"- "," ")) -> 0.34073477 | H15: =IF('[3]actual CWTs exp'!H12/'[3]actual CWTs exp'!$AC12>0.0005,'[3]actual CWTs exp'!H12/'[3]actual CWTs exp'!$AC12,IF('[3]actual CWTs exp'!H12/'[3]actual CWTs exp'!$AC12>0,"- "," ")) -> 0.017155773 | I15: =IF('[3]actual CWTs exp'!I12/'[3]actual CWTs exp'!$AC12>0.0005,'[3]actual CWTs exp'!I12/'[3]actual CWTs exp'!$AC12,IF('[3]actual CWTs exp'!I12/'[3]actual CWTs exp'!$AC12>0,"- "," ")) -> - | J15: =IF('[3]actual CWTs exp'!J12/'[3]actual CWTs exp'!$AC12>0.0005,'[3]actual CWTs exp'!J12/'[3]actual CWTs exp'!$AC12,IF('[3]actual CWTs exp'!J12/'[3]actual CWTs exp'!$AC12>0,"- "," ")) -> 0.0098840225 | K15: =IF('[3]actual CWTs exp'!K12/'[3]actual CWTs exp'!$AC12>0.0005,'[3]actual CWTs exp'!K12/'[3]actual CWTs exp'!$AC12,IF('[3]actual CWTs exp'!K12/'[3]actual CWTs exp'!$AC12>0,"- "," ")) -> 0.012283237 | L15: =IF('[3]actual CWTs exp'!L12/'[3]actual CWTs exp'!$AC12>0.0005,'[3]actual CWTs exp'!L12/'[3]actual CWTs exp'!$AC12,IF('[3]actual CWTs exp'!L12/'[3]actual CWTs exp'!$AC12>0,"- "," ")) -> 0.0050114866 | ... Z15: =IF('[3]actual CWTs exp'!Z12/'[3]actual CWTs exp'!$AC12>0.0005,'[3]actual CWTs exp'!Z12/'[3]actual CWTs exp'!$AC12,IF('[3]actual CWTs exp'!Z12/'[3]actual CWTs exp'!$AC12>0,"- "," ")) | AA15: =IF('[3]actual CWTs exp'!AA12>0,'[3]actual CWTs exp'!AA12/'[3]actual CWTs exp'!$AC12," ") -> 0.88507855 | AB15: =IF('[3]actual CWTs exp'!AB12>0,'[3]actual CWTs exp'!AB12/'[3]actual CWTs exp'!$AC12," ") -> 0.11492145 | AC15: ='[3]actual CWTs exp'!AC12 -> 107952
A17: Natural Spawners | AC17: ='[3]actual CWTs exp'!AC13 -> 0
A18: Upper Sacramento River | B18: USAC | C18: 54 | D18: Late | E18: =IF('[3]actual CWTs exp'!E14/'[3]actual CWTs exp'!$AC14>0.0005,'[3]actual CWTs exp'!E14/'[3]actual CWTs exp'!$AC14,IF('[3]actual CWTs exp'!E14/'[3]actual CWTs exp'!$AC14>0,"- "," ")) -> 0.37154362 | F18: =IF('[3]actual CWTs exp'!F14/'[3]actual CWTs exp'!$AC14>0.0005,'[3]actual CWTs exp'!F14/'[3]actual CWTs exp'!$AC14,IF('[3]actual CWTs exp'!F14/'[3]actual CWTs exp'!$AC14>0,"- "," ")) -> 0.039731544 | G18: =IF('[3]actual CWTs exp'!G14/'[3]actual CWTs exp'!$AC14>0.0005,'[3]actual CWTs exp'!G14/'[3]actual CWTs exp'!$AC14,IF('[3]actual CWTs exp'!G14/'[3]actual CWTs exp'!$AC14>0,"- "," ")) | H18: =IF('[3]actual CWTs exp'!H14/'[3]actual CWTs exp'!$AC14>0.0005,'[3]actual CWTs exp'!H14/'[3]actual CWTs exp'!$AC14,IF('[3]actual CWTs exp'!H14/'[3]actual CWTs exp'!$AC14>0,"- "," ")) | I18: =IF('[3]actual CWTs exp'!I14/'[3]actual CWTs exp'!$AC14>0.0005,'[3]actual CWTs exp'!I14/'[3]actual CWTs exp'!$AC14,IF('[3]actual CWTs exp'!I14/'[3]actual CWTs exp'!$AC14>0,"- "," ")) | J18: =IF('[3]actual CWTs exp'!J14/'[3]actual CWTs exp'!$AC14>0.0005,'[3]actual CWTs exp'!J14/'[3]actual CWTs exp'!$AC14,IF('[3]actual CWTs exp'!J14/'[3]actual CWTs exp'!$AC14>0,"- "," ")) | K18: =IF('[3]actual CWTs exp'!K14/'[3]actual CWTs exp'!$AC14>0.0005,'[3]actual CWTs exp'!K14/'[3]actual CWTs exp'!$AC14,IF('[3]actual CWTs exp'!K14/'[3]actual CWTs exp'!$AC14>0,"- "," ")) | L18: =IF('[3]actual CWTs exp'!L14/'[3]actual CWTs exp'!$AC14>0.0005,'[3]actual CWTs exp'!L14/'[3]actual CWTs exp'!$AC14,IF('[3]actual CWTs exp'!L14/'[3]actual CWTs exp'!$AC14>0,"- "," ")) | ... Z18: =IF('[3]actual CWTs exp'!Z14/'[3]actual CWTs exp'!$AC14>0.0005,'[3]actual CWTs exp'!Z14/'[3]actual CWTs exp'!$AC14,IF('[3]actual CWTs exp'!Z14/'[3]actual CWTs exp'!$AC14>0,"- "," ")) | AA18: =SUM(E18:Z18) -> 0.44375839 | AB18: =1-AA18 -> 0.55624161 | AC18: ='[3]actual CWTs exp'!AC14 -> 3725
A19: Butte Creek | D19: Spring | E19: =IF('[3]actual CWTs exp'!E15/'[3]actual CWTs exp'!$AC15>0.0005,'[3]actual CWTs exp'!E15/'[3]actual CWTs exp'!$AC15,IF('[3]actual CWTs exp'!E15/'[3]actual CWTs exp'!$AC15>0,"- "," ")) | F19: =IF('[3]actual CWTs exp'!F15/'[3]actual CWTs exp'!$AC15>0.0005,'[3]actual CWTs exp'!F15/'[3]actual CWTs exp'!$AC15,IF('[3]actual CWTs exp'!F15/'[3]actual CWTs exp'!$AC15>0,"- "," ")) | G19: =IF('[3]actual CWTs exp'!G15/'[3]actual CWTs exp'!$AC15>0.0005,'[3]actual CWTs exp'!G15/'[3]actual CWTs exp'!$AC15,IF('[3]actual CWTs exp'!G15/'[3]actual CWTs exp'!$AC15>0,"- "," ")) | H19: =IF('[3]actual CWTs exp'!H15/'[3]actual CWTs exp'!$AC15>0.0005,'[3]actual CWTs exp'!H15/'[3]actual CWTs exp'!$AC15,IF('[3]actual CWTs exp'!H15/'[3]actual CWTs exp'!$AC15>0,"- "," ")) | I19: =IF('[3]actual CWTs exp'!I15/'[3]actual CWTs exp'!$AC15>0.0005,'[3]actual CWTs exp'!I15/'[3]actual CWTs exp'!$AC15,IF('[3]actual CWTs exp'!I15/'[3]actual CWTs exp'!$AC15>0,"- "," ")) | J19: =IF('[3]actual CWTs exp'!J15/'[3]actual CWTs exp'!$AC15>0.0005,'[3]actual CWTs exp'!J15/'[3]actual CWTs exp'!$AC15,IF('[3]actual CWTs exp'!J15/'[3]actual CWTs exp'!$AC15>0,"- "," ")) | K19: =IF('[3]actual CWTs exp'!K15/'[3]actual CWTs exp'!$AC15>0.0005,'[3]actual CWTs exp'!K15/'[3]actual CWTs exp'!$AC15,IF('[3]actual CWTs exp'!K15/'[3]actual CWTs exp'!$AC15>0,"- "," ")) | L19: =IF('[3]actual CWTs exp'!L15/'[3]actual CWTs exp'!$AC15>0.0005,'[3]actual CWTs exp'!L15/'[3]actual CWTs exp'!$AC15,IF('[3]actual CWTs exp'!L15/'[3]actual CWTs exp'!$AC15>0,"- "," ")) | ... Z19: =IF('[3]actual CWTs exp'!Z15/'[3]actual CWTs exp'!$AC15>0.0005,'[3]actual CWTs exp'!Z15/'[3]actual CWTs exp'!$AC15,IF('[3]actual CWTs exp'!Z15/'[3]actual CWTs exp'!$AC15>0,"- "," ")) | AA19: 1e-06 | AB19: 1 | AC19: ='[3]actual CWTs exp'!AC15 -> 4497
A20: Clear Creek | B20: CLR | C20: 54 | D20: Fall | E20: =IF('[3]actual CWTs exp'!E16/'[3]actual CWTs exp'!$AC16>0.0005,'[3]actual CWTs exp'!E16/'[3]actual CWTs exp'!$AC16,IF('[3]actual CWTs exp'!E16/'[3]actual CWTs exp'!$AC16>0,"- "," ")) | F20: =IF('[3]actual CWTs exp'!F16/'[3]actual CWTs exp'!$AC16>0.0005,'[3]actual CWTs exp'!F16/'[3]actual CWTs exp'!$AC16,IF('[3]actual CWTs exp'!F16/'[3]actual CWTs exp'!$AC16>0,"- "," ")) | G20: =IF('[3]actual CWTs exp'!G16/'[3]actual CWTs exp'!$AC16>0.0005,'[3]actual CWTs exp'!G16/'[3]actual CWTs exp'!$AC16,IF('[3]actual CWTs exp'!G16/'[3]actual CWTs exp'!$AC16>0,"- "," ")) -> 0.023135716 | H20: =IF('[3]actual CWTs exp'!H16/'[3]actual CWTs exp'!$AC16>0.0005,'[3]actual CWTs exp'!H16/'[3]actual CWTs exp'!$AC16,IF('[3]actual CWTs exp'!H16/'[3]actual CWTs exp'!$AC16>0,"- "," ")) | I20: =IF('[3]actual CWTs exp'!I16/'[3]actual CWTs exp'!$AC16>0.0005,'[3]actual CWTs exp'!I16/'[3]actual CWTs exp'!$AC16,IF('[3]actual CWTs exp'!I16/'[3]actual CWTs exp'!$AC16>0,"- "," ")) -> 0.00082627556 | J20: =IF('[3]actual CWTs exp'!J16/'[3]actual CWTs exp'!$AC16>0.0005,'[3]actual CWTs exp'!J16/'[3]actual CWTs exp'!$AC16,IF('[3]actual CWTs exp'!J16/'[3]actual CWTs exp'!$AC16>0,"- "," ")) | K20: =IF('[3]actual CWTs exp'!K16/'[3]actual CWTs exp'!$AC16>0.0005,'[3]actual CWTs exp'!K16/'[3]actual CWTs exp'!$AC16,IF('[3]actual CWTs exp'!K16/'[3]actual CWTs exp'!$AC16>0,"- "," ")) -> 0.0045445156 | L20: =IF('[3]actual CWTs exp'!L16/'[3]actual CWTs exp'!$AC16>0.0005,'[3]actual CWTs exp'!L16/'[3]actual CWTs exp'!$AC16,IF('[3]actual CWTs exp'!L16/'[3]actual CWTs exp'!$AC16>0,"- "," ")) -> 0.00082627556 | ... Z20: =IF('[3]actual CWTs exp'!Z16/'[3]actual CWTs exp'!$AC16>0.0005,'[3]actual CWTs exp'!Z16/'[3]actual CWTs exp'!$AC16,IF('[3]actual CWTs exp'!Z16/'[3]actual CWTs exp'!$AC16>0,"- "," ")) | AA20: =SUM(E20:Z20) -> 0.081181574 | AB20: =1-AA20 -> 0.91881843 | AC20: ='[3]actual CWTs exp'!AC16 -> 4841
A21: Cottonwood Creekᶜ | B21: COT | C21: 54 | D21: Fall | E21: =IF('[3]actual CWTs exp'!E17/'[3]actual CWTs exp'!$AC17>0.0005,'[3]actual CWTs exp'!E17/'[3]actual CWTs exp'!$AC17,IF('[3]actual CWTs exp'!E17/'[3]actual CWTs exp'!$AC17>0,"- "," ")) | F21: =IF('[3]actual CWTs exp'!F17/'[3]actual CWTs exp'!$AC17>0.0005,'[3]actual CWTs exp'!F17/'[3]actual CWTs exp'!$AC17,IF('[3]actual CWTs exp'!F17/'[3]actual CWTs exp'!$AC17>0,"- "," ")) | G21: =IF('[3]actual CWTs exp'!G17/'[3]actual CWTs exp'!$AC17>0.0005,'[3]actual CWTs exp'!G17/'[3]actual CWTs exp'!$AC17,IF('[3]actual CWTs exp'!G17/'[3]actual CWTs exp'!$AC17>0,"- "," ")) -> 0.070895522 | H21: =IF('[3]actual CWTs exp'!H17/'[3]actual CWTs exp'!$AC17>0.0005,'[3]actual CWTs exp'!H17/'[3]actual CWTs exp'!$AC17,IF('[3]actual CWTs exp'!H17/'[3]actual CWTs exp'!$AC17>0,"- "," ")) -> 0.01119403 | I21: =IF('[3]actual CWTs exp'!I17/'[3]actual CWTs exp'!$AC17>0.0005,'[3]actual CWTs exp'!I17/'[3]actual CWTs exp'!$AC17,IF('[3]actual CWTs exp'!I17/'[3]actual CWTs exp'!$AC17>0,"- "," ")) | J21: =IF('[3]actual CWTs exp'!J17/'[3]actual CWTs exp'!$AC17>0.0005,'[3]actual CWTs exp'!J17/'[3]actual CWTs exp'!$AC17,IF('[3]actual CWTs exp'!J17/'[3]actual CWTs exp'!$AC17>0,"- "," ")) | K21: =IF('[3]actual CWTs exp'!K17/'[3]actual CWTs exp'!$AC17>0.0005,'[3]actual CWTs exp'!K17/'[3]actual CWTs exp'!$AC17,IF('[3]actual CWTs exp'!K17/'[3]actual CWTs exp'!$AC17>0,"- "," ")) | L21: =IF('[3]actual CWTs exp'!L17/'[3]actual CWTs exp'!$AC17>0.0005,'[3]actual CWTs exp'!L17/'[3]actual CWTs exp'!$AC17,IF('[3]actual CWTs exp'!L17/'[3]actual CWTs exp'!$AC17>0,"- "," ")) | ... Z21: =IF('[3]actual CWTs exp'!Z17/'[3]actual CWTs exp'!$AC17>0.0005,'[3]actual CWTs exp'!Z17/'[3]actual CWTs exp'!$AC17,IF('[3]actual CWTs exp'!Z17/'[3]actual CWTs exp'!$AC17>0,"- "," ")) | AA21: =SUM(E21:Z21) -> 0.095615672 | AB21: =1-AA21 -> 0.90438433 | AC21: ='[3]actual CWTs exp'!AC17 -> 2144
A22: Mill Creekᶜ | B22: MLC | C22: 54 | D22: Fall | E22: =IF('[3]actual CWTs exp'!E18/'[3]actual CWTs exp'!$AC18>0.0005,'[3]actual CWTs exp'!E18/'[3]actual CWTs exp'!$AC18,IF('[3]actual CWTs exp'!E18/'[3]actual CWTs exp'!$AC18>0,"- "," ")) | F22: =IF('[3]actual CWTs exp'!F18/'[3]actual CWTs exp'!$AC18>0.0005,'[3]actual CWTs exp'!F18/'[3]actual CWTs exp'!$AC18,IF('[3]actual CWTs exp'!F18/'[3]actual CWTs exp'!$AC18>0,"- "," ")) | G22: =IF('[3]actual CWTs exp'!G18/'[3]actual CWTs exp'!$AC18>0.0005,'[3]actual CWTs exp'!G18/'[3]actual CWTs exp'!$AC18,IF('[3]actual CWTs exp'!G18/'[3]actual CWTs exp'!$AC18>0,"- "," ")) -> 0.061952862 | H22: =IF('[3]actual CWTs exp'!H18/'[3]actual CWTs exp'!$AC18>0.0005,'[3]actual CWTs exp'!H18/'[3]actual CWTs exp'!$AC18,IF('[3]actual CWTs exp'!H18/'[3]actual CWTs exp'!$AC18>0,"- "," ")) -> 0.0080808081 | I22: =IF('[3]actual CWTs exp'!I18/'[3]actual CWTs exp'!$AC18>0.0005,'[3]actual CWTs exp'!I18/'[3]actual CWTs exp'!$AC18,IF('[3]actual CWTs exp'!I18/'[3]actual CWTs exp'!$AC18>0,"- "," ")) | J22: =IF('[3]actual CWTs exp'!J18/'[3]actual CWTs exp'!$AC18>0.0005,'[3]actual CWTs exp'!J18/'[3]actual CWTs exp'!$AC18,IF('[3]actual CWTs exp'!J18/'[3]actual CWTs exp'!$AC18>0,"- "," ")) | K22: =IF('[3]actual CWTs exp'!K18/'[3]actual CWTs exp'!$AC18>0.0005,'[3]actual CWTs exp'!K18/'[3]actual CWTs exp'!$AC18,IF('[3]actual CWTs exp'!K18/'[3]actual CWTs exp'!$AC18>0,"- "," ")) | L22: =IF('[3]actual CWTs exp'!L18/'[3]actual CWTs exp'!$AC18>0.0005,'[3]actual CWTs exp'!L18/'[3]actual CWTs exp'!$AC18,IF('[3]actual CWTs exp'!L18/'[3]actual CWTs exp'!$AC18>0,"- "," ")) | ... Z22: =IF('[3]actual CWTs exp'!Z18/'[3]actual CWTs exp'!$AC18>0.0005,'[3]actual CWTs exp'!Z18/'[3]actual CWTs exp'!$AC18,IF('[3]actual CWTs exp'!Z18/'[3]actual CWTs exp'!$AC18>0,"- "," ")) | AA22: =SUM(E22:Z22) -> 0.073400673 | AB22: =1-AA22 -> 0.92659933 | AC22: ='[3]actual CWTs exp'!AC18 -> 1485
A23: Battle Creekᵈ | D23: Fall | E23: =IF('[3]actual CWTs exp'!E19/'[3]actual CWTs exp'!$AC19>0.0005,'[3]actual CWTs exp'!E19/'[3]actual CWTs exp'!$AC19,IF('[3]actual CWTs exp'!E19/'[3]actual CWTs exp'!$AC19>0,"- "," ")) -> 0.0064889099 | F23: =IF('[3]actual CWTs exp'!F19/'[3]actual CWTs exp'!$AC19>0.0005,'[3]actual CWTs exp'!F19/'[3]actual CWTs exp'!$AC19,IF('[3]actual CWTs exp'!F19/'[3]actual CWTs exp'!$AC19>0,"- "," ")) | G23: =IF('[3]actual CWTs exp'!G19/'[3]actual CWTs exp'!$AC19>0.0005,'[3]actual CWTs exp'!G19/'[3]actual CWTs exp'!$AC19,IF('[3]actual CWTs exp'!G19/'[3]actual CWTs exp'!$AC19>0,"- "," ")) -> 0.86774422 | H23: =IF('[3]actual CWTs exp'!H19/'[3]actual CWTs exp'!$AC19>0.0005,'[3]actual CWTs exp'!H19/'[3]actual CWTs exp'!$AC19,IF('[3]actual CWTs exp'!H19/'[3]actual CWTs exp'!$AC19>0,"- "," ")) -> 0.0052147239 | I23: =IF('[3]actual CWTs exp'!I19/'[3]actual CWTs exp'!$AC19>0.0005,'[3]actual CWTs exp'!I19/'[3]actual CWTs exp'!$AC19,IF('[3]actual CWTs exp'!I19/'[3]actual CWTs exp'!$AC19>0,"- "," ")) -> - | J23: =IF('[3]actual CWTs exp'!J19/'[3]actual CWTs exp'!$AC19>0.0005,'[3]actual CWTs exp'!J19/'[3]actual CWTs exp'!$AC19,IF('[3]actual CWTs exp'!J19/'[3]actual CWTs exp'!$AC19>0,"- "," ")) | K23: =IF('[3]actual CWTs exp'!K19/'[3]actual CWTs exp'!$AC19>0.0005,'[3]actual CWTs exp'!K19/'[3]actual CWTs exp'!$AC19,IF('[3]actual CWTs exp'!K19/'[3]actual CWTs exp'!$AC19>0,"- "," ")) | L23: =IF('[3]actual CWTs exp'!L19/'[3]actual CWTs exp'!$AC19>0.0005,'[3]actual CWTs exp'!L19/'[3]actual CWTs exp'!$AC19,IF('[3]actual CWTs exp'!L19/'[3]actual CWTs exp'!$AC19>0,"- "," ")) -> - | ... Z23: =IF('[3]actual CWTs exp'!Z19/'[3]actual CWTs exp'!$AC19>0.0005,'[3]actual CWTs exp'!Z19/'[3]actual CWTs exp'!$AC19,IF('[3]actual CWTs exp'!Z19/'[3]actual CWTs exp'!$AC19>0,"- "," ")) | AA23: =SUM(E23:Z23) -> 0.88560642 | AB23: =1-AA23 -> 0.11439358 | AC23: ='[3]actual CWTs exp'!AC19 -> 12867
A24: Butte Creek | B24: BUTT | C24: 54 | D24: Fall | E24: =IF('[3]actual CWTs exp'!E20/'[3]actual CWTs exp'!$AC20>0.0005,'[3]actual CWTs exp'!E20/'[3]actual CWTs exp'!$AC20,IF('[3]actual CWTs exp'!E20/'[3]actual CWTs exp'!$AC20>0,"- "," ")) | F24: =IF('[3]actual CWTs exp'!F20/'[3]actual CWTs exp'!$AC20>0.0005,'[3]actual CWTs exp'!F20/'[3]actual CWTs exp'!$AC20,IF('[3]actual CWTs exp'!F20/'[3]actual CWTs exp'!$AC20>0,"- "," ")) | G24: =IF('[3]actual CWTs exp'!G20/'[3]actual CWTs exp'!$AC20>0.0005,'[3]actual CWTs exp'!G20/'[3]actual CWTs exp'!$AC20,IF('[3]actual CWTs exp'!G20/'[3]actual CWTs exp'!$AC20>0,"- "," ")) | H24: =IF('[3]actual CWTs exp'!H20/'[3]actual CWTs exp'!$AC20>0.0005,'[3]actual CWTs exp'!H20/'[3]actual CWTs exp'!$AC20,IF('[3]actual CWTs exp'!H20/'[3]actual CWTs exp'!$AC20>0,"- "," ")) -> 0.040572792 | I24: =IF('[3]actual CWTs exp'!I20/'[3]actual CWTs exp'!$AC20>0.0005,'[3]actual CWTs exp'!I20/'[3]actual CWTs exp'!$AC20,IF('[3]actual CWTs exp'!I20/'[3]actual CWTs exp'!$AC20>0,"- "," ")) | J24: =IF('[3]actual CWTs exp'!J20/'[3]actual CWTs exp'!$AC20>0.0005,'[3]actual CWTs exp'!J20/'[3]actual CWTs exp'!$AC20,IF('[3]actual CWTs exp'!J20/'[3]actual CWTs exp'!$AC20>0,"- "," ")) | K24: =IF('[3]actual CWTs exp'!K20/'[3]actual CWTs exp'!$AC20>0.0005,'[3]actual CWTs exp'!K20/'[3]actual CWTs exp'!$AC20,IF('[3]actual CWTs exp'!K20/'[3]actual CWTs exp'!$AC20>0,"- "," ")) | L24: =IF('[3]actual CWTs exp'!L20/'[3]actual CWTs exp'!$AC20>0.0005,'[3]actual CWTs exp'!L20/'[3]actual CWTs exp'!$AC20,IF('[3]actual CWTs exp'!L20/'[3]actual CWTs exp'!$AC20>0,"- "," ")) | ... Z24: =IF('[3]actual CWTs exp'!Z20/'[3]actual CWTs exp'!$AC20>0.0005,'[3]actual CWTs exp'!Z20/'[3]actual CWTs exp'!$AC20,IF('[3]actual CWTs exp'!Z20/'[3]actual CWTs exp'!$AC20>0,"- "," ")) | AA24: =SUM(E24:Z24) -> 0.066825776 | AB24: =1-AA24 -> 0.93317422 | AC24: ='[3]actual CWTs exp'!AC20 -> 419
A25: Upper Sac River | B25: USAC | C25: 54 | D25: Fall | E25: =IF('[3]actual CWTs exp'!E21/'[3]actual CWTs exp'!$AC21>0.0005,'[3]actual CWTs exp'!E21/'[3]actual CWTs exp'!$AC21,IF('[3]actual CWTs exp'!E21/'[3]actual CWTs exp'!$AC21>0,"- "," ")) | F25: =IF('[3]actual CWTs exp'!F21/'[3]actual CWTs exp'!$AC21>0.0005,'[3]actual CWTs exp'!F21/'[3]actual CWTs exp'!$AC21,IF('[3]actual CWTs exp'!F21/'[3]actual CWTs exp'!$AC21>0,"- "," ")) | G25: =IF('[3]actual CWTs exp'!G21/'[3]actual CWTs exp'!$AC21>0.0005,'[3]actual CWTs exp'!G21/'[3]actual CWTs exp'!$AC21,IF('[3]actual CWTs exp'!G21/'[3]actual CWTs exp'!$AC21>0,"- "," ")) -> 0.12387792 | H25: =IF('[3]actual CWTs exp'!H21/'[3]actual CWTs exp'!$AC21>0.0005,'[3]actual CWTs exp'!H21/'[3]actual CWTs exp'!$AC21,IF('[3]actual CWTs exp'!H21/'[3]actual CWTs exp'!$AC21>0,"- "," ")) -> 0.012378343 | I25: =IF('[3]actual CWTs exp'!I21/'[3]actual CWTs exp'!$AC21>0.0005,'[3]actual CWTs exp'!I21/'[3]actual CWTs exp'!$AC21,IF('[3]actual CWTs exp'!I21/'[3]actual CWTs exp'!$AC21>0,"- "," ")) -> 0.0023622791 | J25: =IF('[3]actual CWTs exp'!J21/'[3]actual CWTs exp'!$AC21>0.0005,'[3]actual CWTs exp'!J21/'[3]actual CWTs exp'!$AC21,IF('[3]actual CWTs exp'!J21/'[3]actual CWTs exp'!$AC21>0,"- "," ")) | K25: =IF('[3]actual CWTs exp'!K21/'[3]actual CWTs exp'!$AC21>0.0005,'[3]actual CWTs exp'!K21/'[3]actual CWTs exp'!$AC21,IF('[3]actual CWTs exp'!K21/'[3]actual CWTs exp'!$AC21>0,"- "," ")) -> 0.0034961731 | L25: =IF('[3]actual CWTs exp'!L21/'[3]actual CWTs exp'!$AC21>0.0005,'[3]actual CWTs exp'!L21/'[3]actual CWTs exp'!$AC21,IF('[3]actual CWTs exp'!L21/'[3]actual CWTs exp'!$AC21>0,"- "," ")) -> 0.0035906643 | ... Z25: =IF('[3]actual CWTs exp'!Z21/'[3]actual CWTs exp'!$AC21>0.0005,'[3]actual CWTs exp'!Z21/'[3]actual CWTs exp'!$AC21,IF('[3]actual CWTs exp'!Z21/'[3]actual CWTs exp'!$AC21>0,"- "," ")) | AA25: =SUM(E25:Z25) -> 0.26911084 | AB25: =1-AA25 -> 0.73088916 | AC25: ='[3]actual CWTs exp'!AC21 -> 10583
A26: Feather River | B26: FEA | C26: 54 | D26: Fall | E26: =IF('[3]actual CWTs exp'!E22/'[3]actual CWTs exp'!$AC22>0.0005,'[3]actual CWTs exp'!E22/'[3]actual CWTs exp'!$AC22,IF('[3]actual CWTs exp'!E22/'[3]actual CWTs exp'!$AC22>0,"- "," ")) | F26: =IF('[3]actual CWTs exp'!F22/'[3]actual CWTs exp'!$AC22>0.0005,'[3]actual CWTs exp'!F22/'[3]actual CWTs exp'!$AC22,IF('[3]actual CWTs exp'!F22/'[3]actual CWTs exp'!$AC22>0,"- "," ")) | G26: =IF('[3]actual CWTs exp'!G22/'[3]actual CWTs exp'!$AC22>0.0005,'[3]actual CWTs exp'!G22/'[3]actual CWTs exp'!$AC22,IF('[3]actual CWTs exp'!G22/'[3]actual CWTs exp'!$AC22>0,"- "," ")) | H26: =IF('[3]actual CWTs exp'!H22/'[3]actual CWTs exp'!$AC22>0.0005,'[3]actual CWTs exp'!H22/'[3]actual CWTs exp'!$AC22,IF('[3]actual CWTs exp'!H22/'[3]actual CWTs exp'!$AC22>0,"- "," ")) -> 0.031444945 | I26: =IF('[3]actual CWTs exp'!I22/'[3]actual CWTs exp'!$AC22>0.0005,'[3]actual CWTs exp'!I22/'[3]actual CWTs exp'!$AC22,IF('[3]actual CWTs exp'!I22/'[3]actual CWTs exp'!$AC22>0,"- "," ")) | J26: =IF('[3]actual CWTs exp'!J22/'[3]actual CWTs exp'!$AC22>0.0005,'[3]actual CWTs exp'!J22/'[3]actual CWTs exp'!$AC22,IF('[3]actual CWTs exp'!J22/'[3]actual CWTs exp'!$AC22>0,"- "," ")) -> 0.041616444 | K26: =IF('[3]actual CWTs exp'!K22/'[3]actual CWTs exp'!$AC22>0.0005,'[3]actual CWTs exp'!K22/'[3]actual CWTs exp'!$AC22,IF('[3]actual CWTs exp'!K22/'[3]actual CWTs exp'!$AC22>0,"- "," ")) -> 0.042504599 | L26: =IF('[3]actual CWTs exp'!L22/'[3]actual CWTs exp'!$AC22>0.0005,'[3]actual CWTs exp'!L22/'[3]actual CWTs exp'!$AC22,IF('[3]actual CWTs exp'!L22/'[3]actual CWTs exp'!$AC22>0,"- "," ")) -> 0.018186047 | ... Z26: =IF('[3]actual CWTs exp'!Z22/'[3]actual CWTs exp'!$AC22>0.0005,'[3]actual CWTs exp'!Z22/'[3]actual CWTs exp'!$AC22,IF('[3]actual CWTs exp'!Z22/'[3]actual CWTs exp'!$AC22>0,"- "," ")) | AA26: =SUM(E26:Z26) -> 0.8952822 | AB26: =1-AA26 -> 0.1047178 | AC26: ='[3]actual CWTs exp'!AC22 -> 47289
A27: Yuba River - Above DPD | B27: YUBA | C27: 54 | D27: Fall | E27: =IF('[3]actual CWTs exp'!E23/'[3]actual CWTs exp'!$AC23>0.0005,'[3]actual CWTs exp'!E23/'[3]actual CWTs exp'!$AC23,IF('[3]actual CWTs exp'!E23/'[3]actual CWTs exp'!$AC23>0,"- "," ")) | F27: =IF('[3]actual CWTs exp'!F23/'[3]actual CWTs exp'!$AC23>0.0005,'[3]actual CWTs exp'!F23/'[3]actual CWTs exp'!$AC23,IF('[3]actual CWTs exp'!F23/'[3]actual CWTs exp'!$AC23>0,"- "," ")) | G27: =IF('[3]actual CWTs exp'!G23/'[3]actual CWTs exp'!$AC23>0.0005,'[3]actual CWTs exp'!G23/'[3]actual CWTs exp'!$AC23,IF('[3]actual CWTs exp'!G23/'[3]actual CWTs exp'!$AC23>0,"- "," ")) | H27: =IF('[3]actual CWTs exp'!H23/'[3]actual CWTs exp'!$AC23>0.0005,'[3]actual CWTs exp'!H23/'[3]actual CWTs exp'!$AC23,IF('[3]actual CWTs exp'!H23/'[3]actual CWTs exp'!$AC23>0,"- "," ")) -> 0.088696103 | I27: =IF('[3]actual CWTs exp'!I23/'[3]actual CWTs exp'!$AC23>0.0005,'[3]actual CWTs exp'!I23/'[3]actual CWTs exp'!$AC23,IF('[3]actual CWTs exp'!I23/'[3]actual CWTs exp'!$AC23>0,"- "," ")) | J27: =IF('[3]actual CWTs exp'!J23/'[3]actual CWTs exp'!$AC23>0.0005,'[3]actual CWTs exp'!J23/'[3]actual CWTs exp'!$AC23,IF('[3]actual CWTs exp'!J23/'[3]actual CWTs exp'!$AC23>0,"- "," ")) -> 0.0042729509 | K27: =IF('[3]actual CWTs exp'!K23/'[3]actual CWTs exp'!$AC23>0.0005,'[3]actual CWTs exp'!K23/'[3]actual CWTs exp'!$AC23,IF('[3]actual CWTs exp'!K23/'[3]actual CWTs exp'!$AC23>0,"- "," ")) -> 0.017221287 | L27: =IF('[3]actual CWTs exp'!L23/'[3]actual CWTs exp'!$AC23>0.0005,'[3]actual CWTs exp'!L23/'[3]actual CWTs exp'!$AC23,IF('[3]actual CWTs exp'!L23/'[3]actual CWTs exp'!$AC23>0,"- "," ")) -> 0.01307782 | ... Z27: =IF('[3]actual CWTs exp'!Z23/'[3]actual CWTs exp'!$AC23>0.0005,'[3]actual CWTs exp'!Z23/'[3]actual CWTs exp'!$AC23,IF('[3]actual CWTs exp'!Z23/'[3]actual CWTs exp'!$AC23>0,"- "," ")) | AA27: =SUM(E27:Z27) -> 0.64508611 | AB27: =1-AA27 -> 0.35491389 | AC27: ='[3]actual CWTs exp'!AC23 -> 7723
A28: Yuba River - Below DPD | B28: YUBB | C28: 54 | D28: Fall | E28: =IF('[3]actual CWTs exp'!E24/'[3]actual CWTs exp'!$AC24>0.0005,'[3]actual CWTs exp'!E24/'[3]actual CWTs exp'!$AC24,IF('[3]actual CWTs exp'!E24/'[3]actual CWTs exp'!$AC24>0,"- "," ")) | F28: =IF('[3]actual CWTs exp'!F24/'[3]actual CWTs exp'!$AC24>0.0005,'[3]actual CWTs exp'!F24/'[3]actual CWTs exp'!$AC24,IF('[3]actual CWTs exp'!F24/'[3]actual CWTs exp'!$AC24>0,"- "," ")) | G28: =IF('[3]actual CWTs exp'!G24/'[3]actual CWTs exp'!$AC24>0.0005,'[3]actual CWTs exp'!G24/'[3]actual CWTs exp'!$AC24,IF('[3]actual CWTs exp'!G24/'[3]actual CWTs exp'!$AC24>0,"- "," ")) | H28: =IF('[3]actual CWTs exp'!H24/'[3]actual CWTs exp'!$AC24>0.0005,'[3]actual CWTs exp'!H24/'[3]actual CWTs exp'!$AC24,IF('[3]actual CWTs exp'!H24/'[3]actual CWTs exp'!$AC24>0,"- "," ")) -> 0.057939914 | I28: =IF('[3]actual CWTs exp'!I24/'[3]actual CWTs exp'!$AC24>0.0005,'[3]actual CWTs exp'!I24/'[3]actual CWTs exp'!$AC24,IF('[3]actual CWTs exp'!I24/'[3]actual CWTs exp'!$AC24>0,"- "," ")) | J28: =IF('[3]actual CWTs exp'!J24/'[3]actual CWTs exp'!$AC24>0.0005,'[3]actual CWTs exp'!J24/'[3]actual CWTs exp'!$AC24,IF('[3]actual CWTs exp'!J24/'[3]actual CWTs exp'!$AC24>0,"- "," ")) -> 0.0050071531 | K28: =IF('[3]actual CWTs exp'!K24/'[3]actual CWTs exp'!$AC24>0.0005,'[3]actual CWTs exp'!K24/'[3]actual CWTs exp'!$AC24,IF('[3]actual CWTs exp'!K24/'[3]actual CWTs exp'!$AC24>0,"- "," ")) -> 0.010014306 | L28: =IF('[3]actual CWTs exp'!L24/'[3]actual CWTs exp'!$AC24>0.0005,'[3]actual CWTs exp'!L24/'[3]actual CWTs exp'!$AC24,IF('[3]actual CWTs exp'!L24/'[3]actual CWTs exp'!$AC24>0,"- "," ")) -> 0.0050071531 | ... Z28: =IF('[3]actual CWTs exp'!Z24/'[3]actual CWTs exp'!$AC24>0.0005,'[3]actual CWTs exp'!Z24/'[3]actual CWTs exp'!$AC24,IF('[3]actual CWTs exp'!Z24/'[3]actual CWTs exp'!$AC24>0,"- "," ")) | AA28: =SUM(E28:Z28) -> 0.33905579 | AB28: =1-AA28 -> 0.66094421 | AC28: ='[3]actual CWTs exp'!AC24 -> 1398
